#!/usr/bin/env python
# -*- coding: utf-8 -*-

"""
test_python-business-logic
------------

Tests for `python-business-logic` external API.
"""

import mock
from unittest import TestCase

from business_logic import core, exceptions


class TestPermissionResult(TestCase):

    def test_string_representation_equals_to_error(self):
        result = core.ValidationResult(success=False, error=Exception("Test error"))
        self.assertEqual(str(result), "Test error")

    def test_permission_result_coercible_to_bool(self):
        result_success = core.ValidationResult(success=True)
        result_failure = core.ValidationResult(success=False)
        self.assertTrue(result_success)
        self.assertFalse(result_failure)

    def test_permission_result_delegates_errors_and_error_code(self):
        exception = exceptions.LogicException("test", error_code="CODE", errors=object())
        result = core.ValidationResult(success=False, error=exception)
        self.assertEqual(result.error_code, exception.error_code)
        self.assertEqual(result.errors, exception.errors)

    def test_permission_result_delegates_returns_none_if_no_error(self):
        result = core.ValidationResult(success=True, error=None)
        self.assertIsNone(result.error_code)
        self.assertIsNone(result.errors)

    def test_permission_result_repr(self):
        result_success = core.ValidationResult(success=True)
        self.assertEqual(
            repr(result_success),
            u'<PermissionResult success=True error=None>')

    def test_comparision(self):
        success_result = core.ValidationResult(success=True)
        failure_result = core.ValidationResult(success=False)
        self.assertEqual(success_result, True)
        self.assertEqual(failure_result, False)
        self.assertNotEqual(success_result, failure_result)

        # comparision with other types should raise false
        self.assertFalse(success_result == 1)

    def test_unicode_is_handled_properly(self):
        unicode_text = u'Zażółć gęślą jaźń'
        result = core.ValidationResult(success=False, error=exceptions.LogicException(unicode_text))
        self.assertEqual(u'{}'.format(result), unicode_text)


class TestValidator(TestCase):

    def setUp(self):
        self.mock_validator = mock.MagicMock()
        self.mock_validator.__name__ = 'python2_fix'
        self.decorated_validator = core.validator(self.mock_validator)

    def test_validator_raises_exception(self):
        self.mock_validator.side_effect = exceptions.LogicException()
        self.assertRaises(
            exceptions.LogicException,
            lambda: self.decorated_validator())
        self.assertRaises(
            exceptions.LogicException,
            lambda: self.decorated_validator(raise_exception=True))

    def test_passed_validator_returns_success_validation_result(self):
        self.mock_validator.return_value = None
        # when validator passes, raise_exception parameter shouldn't make any difference
        success1 = self.decorated_validator(raise_exception=False)
        success2 = self.decorated_validator(raise_exception=True)
        self.assertIsInstance(success1, core.ValidationResult)
        self.assertIsInstance(success2, core.ValidationResult)
        self.assertTrue(success1)
        self.assertTrue(success2)
        self.assertEqual(success1, success2)

    def test_validator_returns_false_permission_when_exception_raised_and_caught(self):
        self.mock_validator.side_effect = exceptions.LogicException()
        failure1 = self.decorated_validator(raise_exception=False)
        self.assertIsInstance(failure1, core.ValidationResult)
        self.assertFalse(failure1)

    def test_generic_services_exception_is_raised_when_validator_return_false(self):
        self.mock_validator.return_value = False
        self.assertRaises(
            core.LogicException,
            lambda: self.decorated_validator(raise_exception=True))

    def test_returned_failure_contains_exception(self):
        self.mock_validator.side_effect = exceptions.LogicException()
        result = self.decorated_validator(raise_exception=False)
        self.assertFalse(result)
        self.assertFalse(result.success)
        self.assertIsInstance(result.error, exceptions.LogicException)
        # it should be none because exception is not created using ServiceErrors
        self.assertIsNone(result.errors)
        self.assertIsNone(result.error_code)

    def test_raise_exception_argument_is_swallowed(self):
        self.decorated_validator()
        self.mock_validator.assert_called_with()

        self.decorated_validator(raise_exception=False)
        self.mock_validator.assert_called_with()

        self.decorated_validator(raise_exception=True)
        self.mock_validator.assert_called_with()

    def test_other_args_are_passed_unchanged(self):
        self.decorated_validator(1, 2, a=3, b=4)
        self.mock_validator.assert_called_with(1, 2, a=3, b=4)


class TestValidatedBy(TestCase):

    def setUp(self):
        self.mock_validator = mock.MagicMock()
        self.validated_func = mock.MagicMock()
        self.validated_func.__name__ = 'python2_fix'
        self.decorated_validated_func = core.validated_by(self.mock_validator)(self.validated_func)

    def test_validated_by_swallows_validate_parameter(self):
        self.decorated_validated_func()
        self.validated_func.assert_called_with()

        self.decorated_validated_func(validate=True)
        self.validated_func.assert_called_with()

        self.decorated_validated_func(validate=True)
        self.validated_func.assert_called_with()

    def test_validate_true_calls_validator_with_raise_true(self):
        self.decorated_validated_func(validate=True)
        self.mock_validator.assert_called_with(raise_exception=True)

        self.decorated_validated_func()
        self.mock_validator.assert_called_with(raise_exception=True)

    def test_validate_false_skips_vaidator_entirely(self):
        self.decorated_validated_func(validate=False)
        self.assertFalse(self.mock_validator.called)

    def test_other_parameters_are_passed_to_both_func_and_validator(self):
        self.decorated_validated_func(1, 2, a=3, b=4)
        self.mock_validator.assert_called_with(1, 2, a=3, b=4, raise_exception=True)
        self.validated_func.assert_called_with(1, 2, a=3, b=4)

    def test_exception_from_validator_is_raised(self):
        self.mock_validator.side_effect = exceptions.LogicException("Fail!")
        self.assertRaises(exceptions.LogicException, self.mock_validator)
